2024-12-15 22:26:41,361 | ERROR | Ошибка
Traceback (most recent call last):
  File "C:\Users\Надежда\PycharmProjects\LoggingRunners\tests_12_4.py", line 27, in test_run
    r2 = rt.Runner(19,15)
  File "C:\Users\Надежда\PycharmProjects\LoggingRunners\rt_with_exceptions.py", line 6, in __init__
    raise TypeError(f'Имя может быть только строкой, передано {type(name).__name__}')
TypeError: Имя может быть только строкой, передано int
2024-12-15 22:26:41,365 | WARNING | Неверный тип данных для объекта Runner
2024-12-15 22:26:41,365 | INFO | "test_run" выполнен успешно
2024-12-15 22:26:41,366 | ERROR | Ошибка
Traceback (most recent call last):
  File "C:\Users\Надежда\PycharmProjects\LoggingRunners\tests_12_4.py", line 15, in test_walk
    r1 = rt.Runner('Name', -10)
  File "C:\Users\Надежда\PycharmProjects\LoggingRunners\rt_with_exceptions.py", line 11, in __init__
    raise ValueError(f'Скорость не может быть отрицательной, сейчас {speed}')
ValueError: Скорость не может быть отрицательной, сейчас -10
2024-12-15 22:26:41,366 | WARNING | Неверная скорость для Runner
2024-12-15 22:26:41,366 | INFO | "test_walk" выполнен успешно
